2021-03-05 01:03:05.011327: W tensorflow/stream_executor/platform/default/dso_loader.cc:60] Could not load dynamic library 'libcudart.so.11.0'; dlerror: libcudart.so.11.0: cannot open shared object file: No such file or directory; LD_LIBRARY_PATH: /project2/rkessler/PRODUCTS/snpca/local/snfit/lib:/software/intel/parallel_studio_xe_2020_update1/lib/intel64/:/lib64:/software/intel/parallel_studio_xe_2020_update1/lib/intel64:/project2/rkessler/PRODUCTS/CosmoMC/planck/plc_3.0/plc-3.01/lib:/lib:/software/intel/parallel_studio_xe_2020_update1/compilers_and_libraries_2020.1.217/linux/compiler/lib/intel64_lin:/software/intel/parallel_studio_xe_2020_update1/impi/2019.7.217/intel64/lib:/software/intel/parallel_studio_xe_2020_update1/impi/2019.7.217/intel64/lib/release:/software/intel/parallel_studio_xe_2020_update1/impi/2019.7.217/intel64/libfabric/lib:/software/intel/parallel_studio_xe_2020_update1/tbb/lib/intel64/gcc4.8:/software/intel/parallel_studio_xe_2020_update1/ipp/lib/intel64:/software/python-anaconda-2020.02-el7-x86_64/lib:/software/ROOT-5.34.14-el7-x86_64/lib:/software/hdf5-1.8.17-el7-x86_64/lib:/software/python_ucs4-2.7.12-el7-x86_64/lib:/software/intel/parallel_studio_xe_2016_update3/mkl/lib/intel64:/software/qt-4.8-el7-x86_64/lib:/software/fftw3-3.3.5-el7-x86_64/lib:/software/gsl-1.16-el7-x86_64/lib:/software/graphviz-2.38-el7-x86_64/lib:/software/cernlib-2006b-el7-x86_64/2006b/lib:/software/cfitsio-3-el7-x86_64/lib:/software/git-2.10-el7-x86_64/lib64:/software/subversion-1.9.4-el7-x86_64/lib:/software/serf-1.3.9-el7-x86_64/lib:/software/slurm-current-el7-x86_64/lib64:/software/slurm-current-el7-x86_64/lib:/project2/rkessler/PRODUCTS/snpca/local/snfit/lib:/project2/rkessler/PRODUCTS/snpca/local/snfit/lib:/project2/rkessler/PRODUCTS/snpca/local/snfit/lib
2021-03-05 01:03:05.011514: I tensorflow/stream_executor/cuda/cudart_stub.cc:29] Ignore above cudart dlerror if you do not have a GPU set up on your machine.
writing to /project2/rkessler/SURVEYS/DES/USERS/helenqu/test_create_heatmaps
create_heatmaps_utils.py:171: YAMLLoadWarning: calling yaml.load() without Loader=... is deprecated, as the default Loader is unsafe. Please read https://msg.pyyaml.org/load for full details.
  config = yaml.load(cfgfile)
Traceback (most recent call last):
  File "create_heatmaps_utils.py", line 192, in <module>
    ids_file = h5py.File(IDS_PATH, "r")
NameError: name 'IDS_PATH' is not defined
